# try-and-catch

A minimal TypeScript utility for safe try-catch execution, supporting both sync and async functions with enhanced error handling, resource safety, and retry mechanisms.

## Features

‚úÖ **Sync & Async Support** - Works with both synchronous and asynchronous functions  
‚úÖ **Finally Callbacks** - Optional cleanup callbacks that always execute  
‚úÖ **Enhanced Error Context** - Preserves original error objects, stack traces, and custom properties  
‚úÖ **Resource Safety** - Finally callbacks are protected and won't break your main logic  
‚úÖ **Built-in Retry Mechanisms** - Configurable retry logic with exponential backoff  
‚úÖ **Smart Error Classification** - Built-in utilities to identify and handle different error types  
‚úÖ **TypeScript Support** - Full type safety with proper overloads  
‚úÖ **Zero Dependencies** - Lightweight and focused

## Installation

```bash
npm install try-and-catch
```

## üî• Strong Recommendation

**This package is enterprise-ready and production-tested.** If you're working with error-prone operations like API calls, file I/O, or database queries, this utility will significantly improve your code's reliability and maintainability. The enhanced error context preservation and built-in retry mechanisms make it invaluable for production applications where robust error handling is critical.

**Perfect for:** REST API clients, database operations, file processing, network requests, microservices communication, and any scenario where graceful error handling with retry logic is essential.

## Usage

```typescript
import { 
  tryAndCatch, 
  tryAndCatchWithRetry, 
  ErrorTypes, 
  RetryStrategies,
  Result 
} from 'try-and-catch';

// Basic usage - synchronous
const result = tryAndCatch(() => {
  return JSON.parse('{"valid": true}');
});
console.log(result); // { result: { valid: true }, error: null }

// Basic usage - asynchronous
const asyncResult = await tryAndCatch(async () => {
  const response = await fetch('/api/data');
  return response.json();
});

// Enhanced error handling with preserved context
const errorResult = tryAndCatch(() => {
  const err = new Error('Database connection failed');
  err.code = 'ECONNREFUSED';
  err.errno = 1042;
  throw err;
});
// All original error properties are preserved!
console.log(errorResult.error?.code); // 'ECONNREFUSED'
console.log(errorResult.error?.errno); // 1042

// Resource management with finally callback
const withCleanup = await tryAndCatch(
  async () => {
    const connection = await openDatabase();
    return await connection.query('SELECT * FROM users');
  },
  async () => {
    // This ALWAYS runs, even on errors
    await closeDatabase();
    console.log('Database connection closed');
  }
);

// Retry mechanisms for unreliable operations
const retryResult = await tryAndCatchWithRetry(
  async () => {
    // This might fail due to network issues
    const response = await fetch('/api/unreliable-endpoint');
    if (!response.ok) throw new Error(`HTTP ${response.status}`);
    return response.json();
  },
  {
    maxRetries: 3,
    delay: RetryStrategies.exponentialBackoff(1000, 10000),
    shouldRetry: ErrorTypes.isRetryable
  }
);
console.log(retryResult.attempts); // Number of attempts made
console.log(retryResult.errors); // All errors encountered

// Smart error classification
const { error } = tryAndCatch(() => {
  throw new Error('Network timeout');
});

if (error) {
  console.log('Is network error:', ErrorTypes.isNetworkError(error));
  console.log('Is retryable:', ErrorTypes.isRetryable(error));
  console.log('Error summary:', ErrorTypes.getErrorSummary(error));
}
```

## Why This Implementation?

This package addresses critical issues found in many try-catch utilities:

### üóëÔ∏è **Resource Leak Prevention**
```typescript
// ‚ùå Other implementations: Resource leaks on errors
// ‚úÖ Our implementation: Always cleans up
const { result, error } = await tryAndCatch(
  async () => {
    const handle = await openFileHandle();
    throw new Error('Processing failed');
  },
  async () => {
    await closeFileHandle(); // ALWAYS executes
  }
);
```

### üîó **Error Context Preservation**
```typescript
// ‚ùå Other implementations: Lose error details
// ‚úÖ Our implementation: Preserves everything
const dbError = new Error('Connection failed');
dbError.code = 'ECONNREFUSED';
dbError.errno = 1042;

const { error } = tryAndCatch(() => { throw dbError; });
console.log(error === dbError); // true - exact same object!
```

### üõ°Ô∏è **Finally Callback Safety**
```typescript
// ‚ùå Other implementations: Finally errors break everything  
// ‚úÖ Our implementation: Finally errors are isolated
const { result, error } = await tryAndCatch(
  async () => 'Success!',
  async () => {
    throw new Error('Cleanup failed'); // Logged, doesn't affect result
  }
);
console.log(result); // 'Success!' - main result preserved
```

## ‚úÖ Limitations SOLVED in v4.1.0

**All major limitations from v4.0.0 have been addressed:**

### üéØ **Memory Management** - ‚úÖ FIXED
- **Solution**: Configurable error history limits (`maxErrorHistory`)
- **Solution**: Compact serializable error representations
- **Solution**: Automatic cleanup of old error entries
- **Result**: Memory usage remains constant even with many retries

### ‚ö° **Performance Optimizations** - ‚úÖ FIXED
- **Solution**: Per-attempt timeout support (`timeout` option)
- **Solution**: Abort signal support for early termination
- **Solution**: Execution time tracking for monitoring
- **Result**: Better control over performance and resource usage

### üõ°Ô∏è **Enhanced Cleanup Handling** - ‚úÖ FIXED
- **Solution**: Custom cleanup error handlers (`onCleanupError`)
- **Solution**: Original error preservation when cleanup fails
- **Solution**: Detailed error context logging
- **Result**: No more lost errors, better resource management

### üìù **JSON Serialization** - ‚úÖ FIXED
- **Solution**: `ErrorUtils.toJSON()` for safe error serialization
- **Solution**: Circular reference protection
- **Solution**: `ErrorUtils.stringify()` with fallback handling
- **Result**: All errors can be safely serialized and logged

### üîí **Concurrency Protection** - ‚úÖ FIXED
- **Solution**: `ConcurrencyUtils.createMutex()` for exclusive access
- **Solution**: `ConcurrencyUtils.createSemaphore()` for limited concurrency
- **Solution**: `ConcurrencyUtils.tryAndCatchWithMutex()` for protected operations
- **Result**: Race conditions eliminated, shared state protected

### üéØ **Complexity Reduction** - ‚úÖ FIXED
- **Solution**: `SimpleRetry.quick()`, `SimpleRetry.network()`, `SimpleRetry.database()`
- **Solution**: Smart defaults for common scenarios
- **Solution**: Simplified APIs that hide complexity
- **Result**: Easy-to-use functions for 90% of use cases

### üîÑ **Remaining Intentional Limitations:**

#### ‚ö†Ô∏è **Learning Curve**
- **Status**: Mitigated with `SimpleRetry` functions
- **Recommendation**: Start with `SimpleRetry`, graduate to full API as needed

**v4.1.0 Achievement:** This package now provides enterprise-grade error handling with minimal complexity, excellent performance, and robust memory management!

## API

### Core Functions

#### `tryAndCatch<T>(fn: () => T | Promise<T>, onFinally?: () => void | Promise<void>): Result<T> | Promise<Result<T>>`

**Parameters:**
- `fn`: Function to execute (sync or async)
- `onFinally`: Optional callback (sync or async) that runs after execution

**Returns:** `{ result, error }` object or Promise of such object

#### `tryAndCatchWithRetry<T>(fn: () => T | Promise<T>, options: RetryOptions, onFinally?: () => void | Promise<void>): Promise<RetryResult<T>>`

**Parameters:**
- `fn`: Function to execute (sync or async)
- `options`: Enhanced retry configuration (see below)
- `onFinally`: Optional cleanup callback

**Returns:** Promise of `{ result, error, attempts, errors, totalTime, lastError }` object

### Type Definitions

```typescript
type Result<T> = {
  result: T | null;    // The value returned by fn, or null on error
  error: Error | null; // The error thrown by fn, or null on success
}

type RetryResult<T> = Result<T> & {
  attempts: number;           // Number of attempts made
  errors: SerializableError[]; // Serializable error history (memory-safe)
  totalTime: number;          // Total execution time in milliseconds
  lastError?: Error | null;   // Reference to the actual last error
}

interface RetryOptions {
  maxRetries: number;           // Maximum retry attempts
  delay?: number | ((attempt: number) => number); // Delay between retries
  shouldRetry?: (error: Error) => boolean;         // Custom retry condition
  
  // üÜï Memory Management (v4.1.0)
  maxErrorHistory?: number;     // Limit stored error history (default: 10)
  compactErrors?: boolean;      // Store compact error representations (default: true)
  
  // üÜï Performance Options (v4.1.0)
  timeout?: number;             // Per-attempt timeout in milliseconds
  abortSignal?: AbortSignal;    // External abort signal
  
  // üÜï Enhanced Cleanup (v4.1.0)
  onCleanupError?: (error: Error, originalError?: Error) => void; // Custom cleanup error handler
}

interface SerializableError {
  name: string;
  message: string;
  stack?: string;
  code?: string | number;
  status?: number;
  errno?: number;
  timestamp: number;
  properties: Record<string, any>;
}
```

### üÜï Simplified API (v4.1.0)

#### `SimpleRetry` - Easy-to-use presets

```typescript
// Quick retry with smart defaults
await SimpleRetry.quick(operation, maxRetries = 3)

// Network-specific retry
await SimpleRetry.network(operation, maxRetries = 5) 

// Database operation retry
await SimpleRetry.database(operation, maxRetries = 3)
```

### üÜï Concurrency Protection (v4.1.0)

#### `ConcurrencyUtils` - Race condition protection

```typescript
// Create mutex for exclusive access
const mutex = ConcurrencyUtils.createMutex()

// Create semaphore for limited concurrency
const semaphore = ConcurrencyUtils.createSemaphore(maxConcurrent)

// Protected operations
await ConcurrencyUtils.tryAndCatchWithMutex(operation, mutex, cleanup)
const protectedFn = ConcurrencyUtils.withMutex(originalFn, mutex)
```

### üÜï Error Utilities (v4.1.0)

#### `ErrorUtils` - Safe error handling

```typescript
// Safe JSON serialization
const serializable = ErrorUtils.toJSON(error)
const jsonString = ErrorUtils.stringify(error)

// Recreate from serialized
const recreated = ErrorUtils.fromJSON(serializable)

// Check serializability
const canSerialize = ErrorUtils.isSerializable(obj)
```

### Error Classification

#### `ErrorTypes`
- `isNetworkError(error)` - Identifies network-related errors
- `isRetryable(error)` - Checks if error should be retried
- `isValidationError(error)` - Identifies validation errors (not retryable)
- `getErrorCode(error)` - Extracts error code/status
- `getErrorSummary(error)` - Gets detailed error information

#### `RetryStrategies`
- `exponentialBackoff(baseDelay?, maxDelay?)` - Exponential backoff with jitter
- `linearBackoff(delay?)` - Linear delay increase
- `fixedDelay(delay?)` - Fixed delay between retries
- `onlyNetworkErrors(error)` - Only retry network errors
- `onlyRetryableErrors(error)` - Only retry transient errors

## Advanced Usage

### Custom Retry Logic
```typescript
const result = await tryAndCatchWithRetry(
  () => unreliableApiCall(),
  {
    maxRetries: 5,
    delay: RetryStrategies.exponentialBackoff(500, 5000),
    shouldRetry: (error) => {
      // Custom logic: only retry on 5xx errors or network issues
      return ErrorTypes.isNetworkError(error) || 
             (error.status >= 500 && error.status < 600);
    }
  },
  () => cleanup() // Always runs after all attempts
);
```

### Complex Error Handling
```typescript
const { error } = tryAndCatch(() => complexOperation());

if (error) {
  const summary = ErrorTypes.getErrorSummary(error);
  
  if (ErrorTypes.isValidationError(error)) {
    console.log('Fix your input:', summary.message);
  } else if (ErrorTypes.isRetryable(error)) {
    console.log('Temporary issue, retry recommended');
  } else {
    console.log('Permanent failure:', summary);
  }
}
```

## TypeScript Support

This package provides full TypeScript support with intelligent type inference:

```typescript
import { tryAndCatch, Result } from 'try-and-catch';

// Function overloads provide correct return types
const syncResult = tryAndCatch(() => 42);
// Type: Result<number>

const asyncResult = await tryAndCatch(async () => 'hello');
// Type: Result<string>

// Export the Result type for your own annotations
const parseUser: Result<User> = tryAndCatch(() => {
  return JSON.parse(userJson) as User;
});

// Type-safe error handling
if (parseUser.error) {
  console.error('Parse failed:', parseUser.error.message);
} else {
  console.log('User ID:', parseUser.result.id); // TypeScript knows result is User
}
```

## Migration from Other Libraries

### From basic try-catch blocks:
```typescript
// ‚ùå Before: Manual error handling
let result;
let error;
try {
  result = await riskyOperation();
} catch (err) {
  error = err;
} finally {
  await cleanup(); // Might throw and break everything!
}

// ‚úÖ After: Safe and clean
const { result, error } = await tryAndCatch(
  () => riskyOperation(),
  () => cleanup() // Safe cleanup
);
```

### From other try-catch utilities:
```typescript
// ‚úÖ Drop-in replacement with better error handling
// Just replace your existing tryAndCatch calls - the API is the same!
const { result, error } = await tryAndCatch(yourFunction, yourCleanup);
```

## License
MIT
